[2022-09-25 22:33:44,394] {taskinstance.py:877} INFO - Dependencies all met for <TaskInstance: Email_Bestseller_List_To_Users.Fiction_book_list 2022-09-25T22:33:40.554243+00:00 [queued]>
[2022-09-25 22:33:44,406] {taskinstance.py:877} INFO - Dependencies all met for <TaskInstance: Email_Bestseller_List_To_Users.Fiction_book_list 2022-09-25T22:33:40.554243+00:00 [queued]>
[2022-09-25 22:33:44,406] {taskinstance.py:1068} INFO - 
--------------------------------------------------------------------------------
[2022-09-25 22:33:44,407] {taskinstance.py:1069} INFO - Starting attempt 1 of 1
[2022-09-25 22:33:44,407] {taskinstance.py:1070} INFO - 
--------------------------------------------------------------------------------
[2022-09-25 22:33:44,422] {taskinstance.py:1089} INFO - Executing <Task(PythonOperator): Fiction_book_list> on 2022-09-25T22:33:40.554243+00:00
[2022-09-25 22:33:44,427] {standard_task_runner.py:52} INFO - Started process 146 to run task
[2022-09-25 22:33:44,433] {standard_task_runner.py:76} INFO - Running: ['airflow', 'tasks', 'run', 'Email_Bestseller_List_To_Users', 'Fiction_book_list', '2022-09-25T22:33:40.554243+00:00', '--job-id', '47', '--pool', 'default_pool', '--raw', '--subdir', 'DAGS_FOLDER/DAG1.py', '--cfg-path', '/tmp/tmp_g_ar1if', '--error-file', '/tmp/tmpszcvbp2c']
[2022-09-25 22:33:44,433] {standard_task_runner.py:77} INFO - Job 47: Subtask Fiction_book_list
[2022-09-25 22:33:44,475] {logging_mixin.py:104} INFO - Running <TaskInstance: Email_Bestseller_List_To_Users.Fiction_book_list 2022-09-25T22:33:40.554243+00:00 [running]> on host d74d0d8a09f8
[2022-09-25 22:33:44,512] {taskinstance.py:1283} INFO - Exporting the following env vars:
AIRFLOW_CTX_DAG_OWNER=airflow
AIRFLOW_CTX_DAG_ID=Email_Bestseller_List_To_Users
AIRFLOW_CTX_TASK_ID=Fiction_book_list
AIRFLOW_CTX_EXECUTION_DATE=2022-09-25T22:33:40.554243+00:00
AIRFLOW_CTX_DAG_RUN_ID=manual__2022-09-25T22:33:40.554243+00:00
[2022-09-25 22:33:44,514] {taskinstance.py:1482} ERROR - Task failed with exception
Traceback (most recent call last):
  File "/home/airflow/.local/lib/python3.6/site-packages/airflow/models/taskinstance.py", line 1138, in _run_raw_task
    self._prepare_and_execute_task_with_callbacks(context, task)
  File "/home/airflow/.local/lib/python3.6/site-packages/airflow/models/taskinstance.py", line 1311, in _prepare_and_execute_task_with_callbacks
    result = self._execute_task(context, task_copy)
  File "/home/airflow/.local/lib/python3.6/site-packages/airflow/models/taskinstance.py", line 1341, in _execute_task
    result = task_copy.execute(context=context)
  File "/home/airflow/.local/lib/python3.6/site-packages/airflow/operators/python.py", line 117, in execute
    return_value = self.execute_callable()
  File "/home/airflow/.local/lib/python3.6/site-packages/airflow/operators/python.py", line 128, in execute_callable
    return self.python_callable(*self.op_args, **self.op_kwargs)
  File "/opt/airflow/dags/DAG1.py", line 50, in Get_Combined_Fiction_Book_List
    List=parse_json['results']['books']
KeyError: 'results'
[2022-09-25 22:33:44,519] {taskinstance.py:1532} INFO - Marking task as FAILED. dag_id=Email_Bestseller_List_To_Users, task_id=Fiction_book_list, execution_date=20220925T223340, start_date=20220925T223344, end_date=20220925T223344
[2022-09-25 22:33:44,565] {local_task_job.py:146} INFO - Task exited with return code 1
